
%s core simulator succeeded Starting
[!] Error: list index out of range

Gracefully shutting down docker.
[+] TestBench Packet parser started
Process ctrl:
[+] Sniffing for packets...
Traceback (most recent call last):
  File "/usr/lib/python3.8/multiprocessing/process.py", line 315, in _bootstrap
    self.run()
  File "/usr/lib/python3.8/multiprocessing/process.py", line 108, in run
    self._target(*self._args, **self._kwargs)
  File "/home/v_diodato/SCAS_5GC/utils/utility.py", line 8, in ctrl
    sckt = socket.socket(socket.AF_INET, socket.SOCK_STREAM)
NameError: name 'socket' is not defined
Process sniff_packets:
Traceback (most recent call last):
  File "/usr/lib/python3.8/multiprocessing/process.py", line 315, in _bootstrap
    self.run()
  File "/usr/lib/python3.8/multiprocessing/process.py", line 108, in run
    self._target(*self._args, **self._kwargs)
  File "SCAScan.py", line 25, in sniff_packets
    packets = sniff(iface=interface,
NameError: name 'interface' is not defined
Traceback (most recent call last):
  File "SCAScan.py", line 74, in <module>
    fun = getattr(testbench, testbench.tests[test]['name'], None)
IndexError: list index out of range

During handling of the above exception, another exception occurred:

Traceback (most recent call last):
  File "SCAScan.py", line 86, in <module>
    testbench.graceful_shutdown(pManager.cmd_q)
  File "/home/v_diodato/SCAS_5GC/utils/testbench.py", line 140, in graceful_shutdown
    subprocess.run(["docker", "logs", nf], stdout=log_file, stderr=subprocess.STDOUT)
  File "/usr/lib/python3.8/subprocess.py", line 493, in run
    with Popen(*popenargs, **kwargs) as process:
  File "/usr/lib/python3.8/subprocess.py", line 808, in __init__
    errread, errwrite) = self._get_handles(stdin, stdout, stderr)
  File "/usr/lib/python3.8/subprocess.py", line 1489, in _get_handles
    c2pwrite = stdout.fileno()
AttributeError: 'str' object has no attribute 'fileno'
Process pktparser:
Traceback (most recent call last):
  File "/usr/lib/python3.8/multiprocessing/managers.py", line 827, in _callmethod
    conn = self._tls.connection
AttributeError: 'ForkAwareLocal' object has no attribute 'connection'

During handling of the above exception, another exception occurred:

Traceback (most recent call last):
  File "/usr/lib/python3.8/multiprocessing/process.py", line 315, in _bootstrap
    self.run()
  File "/usr/lib/python3.8/multiprocessing/process.py", line 108, in run
    self._target(*self._args, **self._kwargs)
  File "/home/v_diodato/SCAS_5GC/utils/testbench.py", line 200, in pktparser
    self.amfip.value = self.__container_ip('amf') #When this function run containers are up and ready
  File "/usr/lib/python3.8/multiprocessing/managers.py", line 1156, in set
    return self._callmethod('set', (value,))
  File "/usr/lib/python3.8/multiprocessing/managers.py", line 831, in _callmethod
    self._connect()
  File "/usr/lib/python3.8/multiprocessing/managers.py", line 818, in _connect
    conn = self._Client(self._token.address, authkey=self._authkey)
  File "/usr/lib/python3.8/multiprocessing/connection.py", line 502, in Client
    c = SocketClient(address)
  File "/usr/lib/python3.8/multiprocessing/connection.py", line 630, in SocketClient
    s.connect(address)
FileNotFoundError: [Errno 2] No such file or directory